{"url":"https://api.github.com/repos/owncloud/core/issues/190","labels_url":"https://api.github.com/repos/owncloud/core/issues/190/labels{/name}","comments_url":"https://api.github.com/repos/owncloud/core/issues/190/comments","events_url":"https://api.github.com/repos/owncloud/core/issues/190/events","html_url":"https://github.com/owncloud/core/issues/190","id":8026562,"number":190,"title":"can't mount google drive - fatal error","user":{"login":"groovy354","id":2697916,"avatar_url":"https://gravatar.com/avatar/a88e1565b32470c045d4dfe3319377c4?d=https%3a%2f%2fidenticons.github.com%2fd614465159f3f8a94baf15dcb28d12b5.png&r=x","gravatar_id":"a88e1565b32470c045d4dfe3319377c4","url":"https://api.github.com/users/groovy354","html_url":"https://github.com/groovy354","followers_url":"https://api.github.com/users/groovy354/followers","following_url":"https://api.github.com/users/groovy354/following{/other_user}","gists_url":"https://api.github.com/users/groovy354/gists{/gist_id}","starred_url":"https://api.github.com/users/groovy354/starred{/owner}{/repo}","subscriptions_url":"https://api.github.com/users/groovy354/subscriptions","organizations_url":"https://api.github.com/users/groovy354/orgs","repos_url":"https://api.github.com/users/groovy354/repos","events_url":"https://api.github.com/users/groovy354/events{/privacy}","received_events_url":"https://api.github.com/users/groovy354/received_events","type":"user","site_admin":false},"labels":[{"url":"https://api.github.com/repos/owncloud/core/labels/app%3afiles_external","name":"app:files_external","color":"02d7e1"},{"url":"https://api.github.com/repos/owncloud/core/labels/bug","name":"bug","color":"fc2929"}],"state":"closed","assignee":null,"milestone":null,"comments":7,"created_at":"2012-11-01t10:09:23z","updated_at":"2013-08-03t13:58:54z","closed_at":"2013-07-03t20:34:46z","pull_request":{"html_url":null,"diff_url":null,"patch_url":null},"body":"after connecting my owncloud with my google account (in order to mount google drive), a blank page with a message \"fatal error: call to a member function getattribute() on a non-object in mypage/owncloud/apps/files_external/lib/google.php on line 496\" appeared and i can't log in no more. please fix it","closed_by":{"login":"vicdeo","id":991300,"avatar_url":"https://gravatar.com/avatar/57b8c1e26d502d5414e4b2fb875d2994?d=https%3a%2f%2fidenticons.github.com%2fe8357fefe8bad5436de368fa5a419461.png&r=x","gravatar_id":"57b8c1e26d502d5414e4b2fb875d2994","url":"https://api.github.com/users/vicdeo","html_url":"https://github.com/vicdeo","followers_url":"https://api.github.com/users/vicdeo/followers","following_url":"https://api.github.com/users/vicdeo/following{/other_user}","gists_url":"https://api.github.com/users/vicdeo/gists{/gist_id}","starred_url":"https://api.github.com/users/vicdeo/starred{/owner}{/repo}","subscriptions_url":"https://api.github.com/users/vicdeo/subscriptions","organizations_url":"https://api.github.com/users/vicdeo/orgs","repos_url":"https://api.github.com/users/vicdeo/repos","events_url":"https://api.github.com/users/vicdeo/events{/privacy}","received_events_url":"https://api.github.com/users/vicdeo/received_events","type":"user","site_admin":false}}